Workbook

Sheet Confronto
A1: CONFRONTO SCENARI — Modello Fiscale K2-AI SRL su €150.000 Utile Lordo
A2: Ipotesi di base: SRL con utile lordo €150.000, due soci-amministratori (Luca Rossi 50% + Jessica Romanelli 50%) tramite Società Semplice. Reddito da dividendi = partecipazione qualificata (>25% capitale SRL non quotata). VERIFICARE TUTTE LE ALIQUOTE CON IL COMMERCIALISTA.
A3: VOCE | B3: SCENARIO A Tutto Compensi | C3: SCENARIO B Tutto Dividendi | D3: SCENARIO C Mix Ottimale | E3: Note
A4: ─── INPUT ───
A5: Utile lordo SRL (€) | B5: =Parametri!B4 -> 150000 | C5: =Parametri!B4 -> 150000 | D5: =Parametri!B4 -> 150000 | E5: Stesso per tutti e 3
A6: ─── LIVELLO SRL ───
A7: IRES pagata da SRL (€) | B7: =Scenario_A!B11 -> 0 | C7: =Scenario_B!B7 -> 36000 | D7: =Scenario_C!B11 -> 20230.4
A8: Totale compensi lordi erogati (€) | B8: =Scenario_A!B5+Scenario_A!B6 -> 127840.91 | C8: 0 | D8: =Scenario_C!B5+Scenario_C!B6 -> 56000
A9: Costo INPS datori SRL (€) | B9: =Scenario_A!B7+Scenario_A!B8 -> 22159.091 | C9: 0 | D9: =Scenario_C!B7+Scenario_C!B8 -> 9706.6667
A10: Utile netto SRL post-IRES (€) | B10: =Scenario_A!B12 -> 0 | C10: =Scenario_B!B8 -> 114000 | D10: =Scenario_C!B12 -> 64062.933
A11: Utile ritenuto in SRL (€) | B11: =Scenario_A!B12 -> 0 | C11: 0 | D11: =Scenario_C!B14 -> 12812.587 | E11: Scen. A: zero perché utile = 0; Scen. B: tutto distribuito
A12: ─── LIVELLO LUCA ───
A13: Cash netto in tasca — Luca (€) | B13: =Scenario_A!B18 -> 40636.989 | C13: =Scenario_B!B15 -> 50440.86 | D13: =Scenario_C!B23 -> 41148.547
A14: INPS lavoratore Luca (€) | B14: =Scenario_A!B15 -> 5539.7727 | C14: 0 | D14: =Scenario_C!B17 -> 2426.6667
A15: IRPEF Luca (€) | B15: =Scenario_A!B17 -> 17743.693 | C15: =Scenario_B!B13 -> 6559.14 | D15: =Scenario_C!B22 -> 10049.959
A16: ─── LIVELLO JESSICA ───
A17: Cash netto in tasca — Jessica (€) | B17: =Scenario_A!B24 -> 40636.989 | C17: =Scenario_B!B21 -> 50440.86 | D17: =Scenario_C!B34 -> 41148.547
A18: INPS lavoratore Jessica (€) | B18: =Scenario_A!B21 -> 5539.7727 | C18: 0 | D18: =Scenario_C!B28 -> 2426.6667
A19: IRPEF Jessica (€) | B19: =Scenario_A!B23 -> 17743.693 | C19: =Scenario_B!B19 -> 6559.14 | D19: =Scenario_C!B33 -> 10049.959
A20: ─── RIEPILOGO TOTALE ───
A21: TOTALE CASH IN TASCA (Luca + Jessica) | B21: =Scenario_A!B26 -> 81273.977 | C21: =Scenario_B!B23 -> 100881.72 | D21: =Scenario_C!B38 -> 82297.095
A22: TOTALE IMPOSTE + ONERI FISCALI/PREV. | B22: =Scenario_A!B30 -> 68726.023 | C22: =Scenario_B!B27 -> 49118.28 | D22: =Scenario_C!B44 -> 54890.319
A23: Utile ritenuto SRL (valore economico, non cash) | B23: 0 | C23: 0 | D23: =Scenario_C!B14 -> 12812.587
A24: Valore economico totale (cash + ritenuto) | B24: =Scenario_A!B26 -> 81273.977 | C24: =Scenario_B!B23 -> 100881.72 | D24: =Scenario_C!B40 -> 95109.681
A25: EFFICIENZA NETTA (netto cash / utile lordo) | B25: =Scenario_A!B32 -> 0.54182652 | C25: =Scenario_B!B29 -> 0.6725448 | D25: =Scenario_C!B45 -> 0.5486473
A26: EFFICIENZA ECONOMICA TOTALE | B26: =Scenario_A!B32 -> 0.54182652 | C26: =Scenario_B!B29 -> 0.6725448 | D26: =Scenario_C!B46 -> 0.63406454 | E26: (incl. ritenuto in SRL)
A28: VERDETTO PROVVISORIO: Scenario B (Tutto Dividendi) massimizza il CASH NETTO (67% efficienza). Scenario C è preferibile quando la SRL deve autofinanziare la crescita. Scenario A è il meno efficiente per la coppia INPS+IRPEF.

Sheet Parametri
A1: MODELLO FISCALE K2-AI SRL — Parametri e Ipotesi di Base
A2: ⚠ ATTENZIONE — SOLO PER DISCUSSIONE CON IL COMMERCIALISTA. Testo BLU su sfondo azzurro = input modificabile dal commercialista. Testo NERO = formula automatica. Non sostituisce consulenza professionale.
A3: Parametro | B3: Valore | C3: Note
A4: Utile lordo SRL — ante compensi e ante IRES (€) | B4: 150000 | C4: Profitto pre-tutto. Modificare qui per testare scenari diversi.
A5: Aliquota IRES | B5: 0.24 | C5: Art. 77 TUIR — aliquota ordinaria 24%
A6: Aliquota INPS gestione separata (totale) | B6: 0.26 | C6: Aliquota indicativa 2024 per iscritti senza altra cov. obbl. — VERIFICARE con c/sta
A7: di cui quota DATORE LAVORO (2/3) | B7: =B6*2/3 -> 0.17333333 | C7: Costo aggiuntivo SRL; si applica in cima al compenso lordo
A8: di cui quota LAVORATORE (1/3) | B8: =B6*1/3 -> 0.086666667 | C8: Trattenuta sull'amministratore, deducibile dal reddito IRPEF
A9: IRPEF 2024 — Scaglione 1: limite superiore (€) | B9: 28000 | C9: 23% su reddito 0 – 28.000 €
A10: IRPEF 2024 — Scaglione 1: aliquota | B10: 0.23
A11: IRPEF 2024 — Scaglione 2: limite superiore (€) | B11: 50000 | C11: 35% su reddito 28.001 – 50.000 €
A12: IRPEF 2024 — Scaglione 2: aliquota | B12: 0.35
A13: IRPEF 2024 — Scaglione 3: aliquota (oltre €50.000) | B13: 0.43 | C13: 43% oltre €50.000
A14: Quota inclusione dividendi qualificati in IRPEF | B14: 0.4972 | C14: Art. 47 c.1 TUIR — partecip. qualificata (>20% voti / >25% cap.). Solo 49,72% del dividendo entra in base IRPEF. NON si applica la ritenuta secca 26%.
A15: Compenso Luca — Scenario C (€) | B15: 28000 | C15: Calibrato al 1° scaglione IRPEF. Modificare per analisi di sensitività.
A16: Compenso Jessica — Scenario C (€) | B16: 28000 | C16: Uguale a Luca per ipotesi di parità SS 50/50
A17: % utile post-IRES distribuito come dividendo — Scenario C | B17: 0.8 | C17: 20% ritenuto in SRL per autofinanziamento crescita K2-AI
A22: Formula IRPEF usata nei scenari: =MIN(X,28000)×23% + MAX(0,MIN(X,50000)−28000)×35% + MAX(0,X−50000)×43%

Sheet Scenario_A
A1: SCENARIO A — TUTTO COMPENSI (Luca + Jessica azzerano utile SRL)
A2: Ipotesi: la SRL distribuisce l'intero utile come compenso agli amministratori, azzerando la base IRES. Ogni euro di profitto passa per IRPEF + INPS gestione separata.
A3: ① SRL — Distribuzione come compenso
A4: Utile lordo SRL (ante compensi, ante IRES) | B4: =Parametri!B4 -> 150000 | C4: Stessa base per tutti e 3 gli scenari
A5: Compenso lordo Luca (calcolato per azzerare utile) | B5: =Parametri!B4/(2*(1+Parametri!B7)) -> 63920.455 | C5: Azzeramento: utile = 2 × comp × (1 + INPS_D)
A6: Compenso lordo Jessica (uguale a Luca) | B6: =B5 -> 63920.455
A7: INPS datore — su compenso Luca | B7: =B5*Parametri!B7 -> 11079.545 | C7: Costo aggiuntivo SRL sopra al compenso lordo
A8: INPS datore — su compenso Jessica | B8: =B6*Parametri!B7 -> 11079.545
A9: Totale costi deducibili SRL (compensi + INPS datori) | B9: =B5+B6+B7+B8 -> 150000 | C9: Dovrebbe ≈ utile lordo SRL
A10: Base imponibile IRES | B10: =B4-B9 -> 0 | C10: ≈ 0 — utile azzerato
A11: IRES pagata da SRL | B11: =B10*Parametri!B5 -> 0 | C11: ≈ 0
A12: Utile netto SRL post-IRES | B12: =B10-B11 -> 0
A13: ② Livello personale — Luca Rossi (amministratore)
A14: Compenso lordo ricevuto | B14: =B5 -> 63920.455
A15: (-) INPS quota lavoratore (1/3 totale INPS) | B15: =B5*Parametri!B8 -> 5539.7727 | C15: Trattenuta deducibile ai fini IRPEF
A16: (=) Reddito imponibile IRPEF | B16: =B14-B15 -> 58380.682 | C16: Base per calcolo IRPEF
A17: (-) IRPEF (scaglioni 23% / 35% / 43%) | B17: =MIN(B16,Parametri!B9)*Parametri!B10+MAX(0,MIN(B16,Parametri!B11)-Parametri!B9)*Parametri!B12+MAX(0,B16-Parametri!B11)*Parametri!B13 -> 17743.693
A18: (=) NETTO IN TASCA — LUCA | B18: =B14-B15-B17 -> 40636.989
A19: ③ Livello personale — Jessica Romanelli (amministratrice)
A20: Compenso lordo ricevuto | B20: =B6 -> 63920.455
A21: (-) INPS quota lavoratore | B21: =B6*Parametri!B8 -> 5539.7727
A22: (=) Reddito imponibile IRPEF | B22: =B20-B21 -> 58380.682
A23: (-) IRPEF (scaglioni 23% / 35% / 43%) | B23: =MIN(B22,Parametri!B9)*Parametri!B10+MAX(0,MIN(B22,Parametri!B11)-Parametri!B9)*Parametri!B12+MAX(0,B22-Parametri!B11)*Parametri!B13 -> 17743.693
A24: (=) NETTO IN TASCA — JESSICA | B24: =B20-B21-B23 -> 40636.989
A25: ④ Riepilogo Scenario A
A26: Totale netto in tasca (Luca + Jessica) | B26: =B18+B24 -> 81273.977
A27: IRES pagata da SRL | B27: =B11 -> 0
A28: INPS totale (datori + lavoratori) | B28: =B7+B8+B15+B21 -> 33238.636
A29: IRPEF totale (Luca + Jessica) | B29: =B17+B23 -> 35487.386
A30: TOTALE IMPOSTE + ONERI FISCALI/PREV. | B30: =B27+B28+B29 -> 68726.023
A31: Utile ritenuto in SRL | B31: =B12 -> 0
A32: EFFICIENZA NETTA (netto / utile lordo) | B32: =B26/Parametri!B4 -> 0.54182652

Sheet Scenario_B
A1: SCENARIO B — TUTTO DIVIDENDI via Società Semplice (SS)
A2: Ipotesi: la SRL non paga compensi. Paga IRES 24% sull'intero utile, poi distribuisce tutto l'utile netto come dividendi alla SS (Luca 50% + Jessica 50%). Dividendi qualificati: 49,72% incluso in IRPEF personale, NO ritenuta secca 26%.
A3: ① SRL — Pagamento IRES e distribuzione utile netto
A4: Utile lordo SRL (ante IRES; nessun compenso) | B4: =Parametri!B4 -> 150000
A5: Nessun compenso pagato agli amministratori | B5: 0 | C5: Compensi = 0 in questo scenario
A6: Base imponibile IRES (= utile lordo) | B6: =B4 -> 150000
A7: IRES pagata (24%) | B7: =B6*Parametri!B5 -> 36000
A8: Utile netto SRL post-IRES (disponibile per distribuzione) | B8: =B6-B7 -> 114000
A9: Dividendo distribuito alla SS (100% dell'utile netto) | B9: =B8 -> 114000 | C9: La SS riceve la totalità; Luca e Jessica al 50% ciascuno
A10: ② Livello personale — Luca Rossi (50% SS → 50% dividendo)
A11: Dividendo lordo SS attribuito a Luca (50%) | B11: =B9*0.5 -> 57000
A12: Quota imponibile IRPEF (49,72% — partecip. qualificata) | B12: =B11*Parametri!B14 -> 28340.4 | C12: Solo 49,72% entra in IRPEF — art. 47 c.1 TUIR
A13: (-) IRPEF (Luca) | B13: =MIN(B12,Parametri!B9)*Parametri!B10+MAX(0,MIN(B12,Parametri!B11)-Parametri!B9)*Parametri!B12+MAX(0,B12-Parametri!B11)*Parametri!B13 -> 6559.14 | C13: Calcolata sugli scaglioni — non ritenuta secca
A14: INPS su dividendi | B14: 0 | C14: Nessuna contribuzione INPS sui dividendi
A15: (=) NETTO IN TASCA — LUCA | B15: =B11-B13 -> 50440.86
A16: ③ Livello personale — Jessica Romanelli (50% SS → 50% dividendo)
A17: Dividendo lordo SS attribuito a Jessica (50%) | B17: =B9*0.5 -> 57000
A18: Quota imponibile IRPEF (49,72%) | B18: =B17*Parametri!B14 -> 28340.4
A19: (-) IRPEF (Jessica) | B19: =MIN(B18,Parametri!B9)*Parametri!B10+MAX(0,MIN(B18,Parametri!B11)-Parametri!B9)*Parametri!B12+MAX(0,B18-Parametri!B11)*Parametri!B13 -> 6559.14
A20: INPS su dividendi | B20: 0 | C20: Nessuna contribuzione INPS sui dividendi
A21: (=) NETTO IN TASCA — JESSICA | B21: =B17-B19 -> 50440.86
A22: ④ Riepilogo Scenario B
A23: Totale netto in tasca (Luca + Jessica) | B23: =B15+B21 -> 100881.72
A24: IRES pagata da SRL | B24: =B7 -> 36000
A25: INPS totale | B25: 0
A26: IRPEF totale (Luca + Jessica) | B26: =B13+B19 -> 13118.28
A27: TOTALE IMPOSTE + ONERI | B27: =B24+B25+B26 -> 49118.28
A28: Utile ritenuto in SRL | B28: 0
A29: EFFICIENZA NETTA (netto / utile lordo) | B29: =B23/Parametri!B4 -> 0.6725448
A30: ⚠ NOTA: I dividendi qualificati (>20% voti o >25% cap.) ricevuti tramite SS confluiscono nel reddito complessivo IRPEF. Se Luca o Jessica hanno altri redditi, l'IRPEF effettiva può essere più alta. Verificare con il commercialista.

Sheet Scenario_C
A1: SCENARIO C — MIX OTTIMALE (Compenso calibrato + Dividendi + Utile ritenuto)
A2: Ipotesi: compenso calibrato al 1° scaglione IRPEF (28.000 €/ciascuno), residuo soggetto a IRES, poi 80% distribuito come dividendo via SS e 20% ritenuto in SRL per autofinanziamento crescita K2-AI.
A3: ① SRL — Compenso parziale + IRES sul residuo + distribuzione
A4: Utile lordo SRL (ante compensi, ante IRES) | B4: =Parametri!B4 -> 150000
A5: Compenso lordo Luca (input — modificabile in Parametri!B15) | B5: =Parametri!B15 -> 28000 | C5: Input BLU in foglio Parametri, riga 15
A6: Compenso lordo Jessica (input — modificabile in Parametri!B16) | B6: =Parametri!B16 -> 28000 | C6: Input BLU in foglio Parametri, riga 16
A7: INPS datore — su compenso Luca | B7: =B5*Parametri!B7 -> 4853.3333
A8: INPS datore — su compenso Jessica | B8: =B6*Parametri!B7 -> 4853.3333
A9: Totale costi deducibili SRL | B9: =B5+B6+B7+B8 -> 65706.667 | C9: Compensi + INPS datori
A10: Base imponibile IRES | B10: =B4-B9 -> 84293.333 | C10: Utile ridotto ma non azzerato
A11: IRES pagata da SRL | B11: =B10*Parametri!B5 -> 20230.4
A12: Utile netto SRL post-IRES | B12: =B10-B11 -> 64062.933 | C12: Disponibile per distribuzione o ritenzione
A13: Dividendo distribuito alla SS (% da Parametri!B17) | B13: =B12*Parametri!B17 -> 51250.347 | C13: 80% in default — modif. in Parametri!B17
A14: Utile ritenuto in SRL (reinvestimento) | B14: =B12-B13 -> 12812.587 | C14: Autofinanziamento; aumenta equity SRL
A15: ② Livello personale — Luca Rossi (compenso + quota dividendo SS)
A16: Compenso lordo | B16: =B5 -> 28000
A17: (-) INPS quota lavoratore | B17: =B5*Parametri!B8 -> 2426.6667 | C17: Deducibile IRPEF
A18: Reddito imponibile da compenso | B18: =B16-B17 -> 25573.333
A19: Dividendo da SS attribuito a Luca (50%) | B19: =B13*0.5 -> 25625.173
A20: Quota imponibile IRPEF del dividendo (49,72%) | B20: =B19*Parametri!B14 -> 12740.836 | C20: Solo 49,72% entra in IRPEF — art. 47 c.1 TUIR
A21: TOTALE reddito imponibile IRPEF (compenso + dividendo) | B21: =B18+B20 -> 38314.17 | C21: I due flussi si sommano in dichiarazione
A22: (-) IRPEF totale (Luca) — scaglioni su reddito cumulato | B22: =MIN(B21,Parametri!B9)*Parametri!B10+MAX(0,MIN(B21,Parametri!B11)-Parametri!B9)*Parametri!B12+MAX(0,B21-Parametri!B11)*Parametri!B13 -> 10049.959 | C22: Il dividendo può "spingere" in uno scaglione superiore
A23: (=) Cash netto Luca: (compenso netto) + (dividendo netto) | B23: =B18+B19-B22 -> 41148.547 | C23: (comp lordo − INPS lav) + dividendo − IRPEF totale
A24: Quota utile ritenuto di pertinenza Luca (50%) | B24: =B14*0.5 -> 6406.2933 | C24: Valore economico non liquido — aumenta equity SS
A25: Valore economico totale Luca (cash + equity ritenuta) | B25: =B23+B24 -> 47554.841
A26: ③ Livello personale — Jessica Romanelli (compenso + quota dividendo SS)
A27: Compenso lordo | B27: =B6 -> 28000
A28: (-) INPS quota lavoratore | B28: =B6*Parametri!B8 -> 2426.6667
A29: Reddito imponibile da compenso | B29: =B27-B28 -> 25573.333
A30: Dividendo da SS attribuito a Jessica (50%) | B30: =B13*0.5 -> 25625.173
A31: Quota imponibile IRPEF del dividendo (49,72%) | B31: =B30*Parametri!B14 -> 12740.836
A32: TOTALE reddito imponibile IRPEF (Jessica) | B32: =B29+B31 -> 38314.17
A33: (-) IRPEF totale (Jessica) | B33: =MIN(B32,Parametri!B9)*Parametri!B10+MAX(0,MIN(B32,Parametri!B11)-Parametri!B9)*Parametri!B12+MAX(0,B32-Parametri!B11)*Parametri!B13 -> 10049.959
A34: (=) Cash netto Jessica | B34: =B29+B30-B33 -> 41148.547
A35: Quota utile ritenuto di pertinenza Jessica (50%) | B35: =B14*0.5 -> 6406.2933
A36: Valore economico totale Jessica | B36: =B34+B35 -> 47554.841
A37: ④ Riepilogo Scenario C
A38: Cash totale in tasca (Luca + Jessica) | B38: =B23+B34 -> 82297.095
A39: Utile ritenuto in SRL (per crescita K2-AI) | B39: =B14 -> 12812.587
A40: Valore economico totale (cash + ritenuto) | B40: =B38+B39 -> 95109.681
...
